<robot name="robot">
  <link name="base_link">
    <visual>
      <origin xyz="0 0 0" rpy="0 0 0" />
      <geometry>
        <cylinder radius="2.5" length="23" />
      </geometry>
      <material name="base_link-material">
        <color rgba="0.8069522576650873 0.8148465722120952 0.8631572134510892 1" />
      </material>
    </visual>
  </link>
  <joint name="base_link_to_cylinder2" type="revolute">
    <parent link="base_link" />
    <child link="cylinder2" />
    <origin xyz="0 0 23" rpy="1.5707963267948963 0 0" />
    <axis xyz="0 0 1"/>
    <limit effort="1000.0" lower="-1.5707963267948966" upper="1.5707963267948966" velocity="0.5"/>  
  </joint>
  <link name="cylinder2">
    <visual>
      <origin xyz="0 0 0" rpy="0 0 0" />
      <geometry>
        <cylinder radius="2.5" length="5" />
      </geometry>
      <material name="cylinder2-material">
        <color rgba="0.2746773120495699 0.13563332964548108 0.0343398068028541 1" />
      </material>
    </visual>
  </link>
  <joint name="cylinder2_to_cylinder3" type="revolute">
    <parent link="cylinder2" />
    <child link="cylinder3" />
    <origin xyz="0 5 0" rpy="0 -1.5707963267948966 0" />
    <axis xyz="0 0 1"/>
    <limit effort="1000.0" lower="-1.5707963267948966" upper="1.5707963267948966" velocity="0.5"/>
  </joint>
  <link name="cylinder3">
    <visual>
      <origin xyz="0 0 0" rpy="0 0 0" />
      <geometry>
        <cylinder radius="2.5" length="5" />
      </geometry>
      <material name="cylinder3-material">
        <color rgba="0.2746773120495699 0.13563332964548108 0.0343398068028541 1" />
      </material>
    </visual>
    <collision>
      <origin xyz="0 0 0" rpy="0 0 0" />
      <geometry>
        <cylinder radius="0" length="0" />
      </geometry>
    </collision>
    <inertial>
      <origin xyz="0 0 0" rpy="0 0 0" />
      <mass value="1" />
      <inertia ixx="0.3333333333333333" ixy="0" ixz="0" iyy="0.5" iyz="0" izz="0.3333333333333333" />
    </inertial>
  </link>
  <joint name="cylinder3_to_cylinder4" type="prismatic">
    <parent link="cylinder3" />
    <child link="cylinder4" />
    <origin xyz="0 8.5 0" rpy="0 -1.5707963267948966 0" />
    <axis xyz="0 0 1"/>
    <limit effort="1000.0" lower="0" upper="1000" velocity="0.5"/>  
  </joint>
  <link name="cylinder4">
    <visual>
      <origin xyz="0 0 0" rpy="0 0 0" />
      <geometry>
        <cylinder radius="0.5" length="10" />
      </geometry>
      <material name="cylinder4-material">
        <color rgba="0.015996293361446288 0.7083757798856457 0.5647115056965487 1" />
      </material>
    </visual>
    <collision>
      <origin xyz="0 0 0" rpy="0 0 0" />
      <geometry>
        <cylinder radius="0" length="0" />
      </geometry>
    </collision>
    <inertial>
      <origin xyz="0 0 0" rpy="0 0 0" />
      <mass value="1" />
      <inertia ixx="0.3333333333333333" ixy="0" ixz="0" iyy="0.5" iyz="0" izz="0.3333333333333333" />
    </inertial>
  </link>
</robot>